Workbook
Name Slicer_Product_category: #N/A
Name Slicer_Store_ID: #N/A

Sheet Customer_Dim
A1: Customer_ID | B1: Name | C1: Name2 | D1: NAME 2 | E1: Age | F1: Gender | G1: City | H1: State | I1: Country | J1: Loyalty_Level | K1: Loyalty_Level3 | L1: Age Category
A2: CUST1000 | B2: sheena bonilla | C2: =PROPER(B2) -> Sheena Bonilla | D2: =TRIM(C2) -> Sheena Bonilla | E2: 55 | F2: Male | G2: Donaldton | H2: North Carolina | I2: USA | K2: =IF(ISBLANK(J2),"UNKNOWN",J2) -> UNKNOWN | L2: =IF(Customer_Dim[[#This Row],[Age]]<25,"Youth", IF(Customer_Dim[[#This Row],[Age]]<=40,"Adult", IF(Customer_Dim[[#This Row],[Age]]<=60,"Middle-Aged","Senior"))) -> Middle-Aged
A3: CUST1001 | B3: Eugene Nelson | C3: =PROPER(B3) -> Eugene Nelson | D3: =TRIM(C3) -> Eugene Nelson | E3: 26 | F3: Female | G3: Phillipsmouth | H3: North Dakota | I3: USA | J3: Platinum | K3: =IF(ISBLANK(J3),"UNKNOWN",J3) -> Platinum | L3: =IF(Customer_Dim[[#This Row],[Age]]<25,"Youth", IF(Customer_Dim[[#This Row],[Age]]<=40,"Adult", IF(Customer_Dim[[#This Row],[Age]]<=60,"Middle-Aged","Senior"))) -> Adult
A4: CUST1002 | B4: dr. Benjamin Price | C4: =PROPER(B4) -> Dr. Benjamin Price | D4: =TRIM(C4) -> Dr. Benjamin Price | E4: 29 | F4: Female | G4: Kylebury | H4: Alabama | I4: USA | J4: Platinum | K4: =IF(ISBLANK(J4),"UNKNOWN",J4) -> Platinum | L4: =IF(Customer_Dim[[#This Row],[Age]]<25,"Youth", IF(Customer_Dim[[#This Row],[Age]]<=40,"Adult", IF(Customer_Dim[[#This Row],[Age]]<=60,"Middle-Aged","Senior"))) -> Adult
A5: CUST1003 | B5: jeremy harris | C5: =PROPER(B5) -> Jeremy Harris | D5: =TRIM(C5) -> Jeremy Harris | E5: 59 | F5: Female | G5: Thomastown | H5: Ohio | I5: USA | J5: Bronze | K5: =IF(ISBLANK(J5),"UNKNOWN",J5) -> Bronze | L5: =IF(Customer_Dim[[#This Row],[Age]]<25,"Youth", IF(Customer_Dim[[#This Row],[Age]]<=40,"Adult", IF(Customer_Dim[[#This Row],[Age]]<=60,"Middle-Aged","Senior"))) -> Middle-Aged
A6: CUST1004 | B6: Caroline Collins | C6: =PROPER(B6) -> Caroline Collins | D6: =TRIM(C6) -> Caroline Collins | E6: 64 | F6: Female | G6: Nicholasshire | H6: California | I6: USA | J6: Silver | K6: =IF(ISBLANK(J6),"UNKNOWN",J6) -> Silver | L6: =IF(Customer_Dim[[#This Row],[Age]]<25,"Youth", IF(Customer_Dim[[#This Row],[Age]]<=40,"Adult", IF(Customer_Dim[[#This Row],[Age]]<=60,"Middle-Aged","Senior"))) -> Senior
A7: CUST1005 | B7: Christine Vaughn | C7: =PROPER(B7) -> Christine Vaughn | D7: =TRIM(C7) -> Christine Vaughn | E7: 24 | F7: Male | G7: East Amandamouth | H7: Oregon | I7: USA | J7: Bronze | K7: =IF(ISBLANK(J7),"UNKNOWN",J7) -> Bronze | L7: =IF(Customer_Dim[[#This Row],[Age]]<25,"Youth", IF(Customer_Dim[[#This Row],[Age]]<=40,"Adult", IF(Customer_Dim[[#This Row],[Age]]<=60,"Middle-Aged","Senior"))) -> Youth
A8: CUST1006 | B8: Amber Jackson | C8: =PROPER(B8) -> Amber Jackson | D8: =TRIM(C8) -> Amber Jackson | E8: 29 | F8: Female | G8: Deborahborough | H8: South Dakota | I8: USA | J8: Platinum | K8: =IF(ISBLANK(J8),"UNKNOWN",J8) -> Platinum | L8: =IF(Customer_Dim[[#This Row],[Age]]<25,"Youth", IF(Customer_Dim[[#This Row],[Age]]<=40,"Adult", IF(Customer_Dim[[#This Row],[Age]]<=60,"Middle-Aged","Senior"))) -> Adult
A9: CUST1007 | B9: Daniel Boyd | C9: =PROPER(B9) -> Daniel Boyd | D9: =TRIM(C9) -> Daniel Boyd | E9: 29 | F9: Female | G9: West Pamelafurt | H9: West Virginia | I9: USA | J9: Bronze | K9: =IF(ISBLANK(J9),"UNKNOWN",J9) -> Bronze | L9: =IF(Customer_Dim[[#This Row],[Age]]<25,"Youth", IF(Customer_Dim[[#This Row],[Age]]<=40,"Adult", IF(Customer_Dim[[#This Row],[Age]]<=60,"Middle-Aged","Senior"))) -> Adult
A10: CUST1008 | B10: Melissa Howard | C10: =PROPER(B10) -> Melissa Howard | D10: =TRIM(C10) -> Melissa Howard | E10: 53 | F10: Female | G10: Maynardton | H10: New Hampshire | I10: USA | J10: Gold | K10: =IF(ISBLANK(J10),"UNKNOWN",J10) -> Gold | L10: =IF(Customer_Dim[[#This Row],[Age]]<25,"Youth", IF(Customer_Dim[[#This Row],[Age]]<=40,"Adult", IF(Customer_Dim[[#This Row],[Age]]<=60,"Middle-Aged","Senior"))) -> Middle-Aged
A11: CUST1009 | B11: Ms. Maria Leach | C11: =PROPER(B11) -> Ms. Maria Leach | D11: =TRIM(C11) -> Ms. Maria Leach | E11: 64 | F11: Male | G11: Melissashire | H11: Pennsylvania | I11: USA | J11: Platinum | K11: =IF(ISBLANK(J11),"UNKNOWN",J11) -> Platinum | L11: =IF(Customer_Dim[[#This Row],[Age]]<25,"Youth", IF(Customer_Dim[[#This Row],[Age]]<=40,"Adult", IF(Customer_Dim[[#This Row],[Age]]<=60,"Middle-Aged","Senior"))) -> Senior
A12: CUST1010 | B12: Dominic Page | C12: =PROPER(B12) -> Dominic Page | D12: =TRIM(C12) -> Dominic Page | E12: 53 | F12: Male | G12: Port Michaelburgh | H12: Pennsylvania | I12: USA | J12: Bronze | K12: =IF(ISBLANK(J12),"UNKNOWN",J12) -> Bronze | L12: =IF(Customer_Dim[[#This Row],[Age]]<25,"Youth", IF(Customer_Dim[[#This Row],[Age]]<=40,"Adult", IF(Customer_Dim[[#This Row],[Age]]<=60,"Middle-Aged","Senior"))) -> Middle-Aged
A13: CUST1011 | B13: Brian Lopez | C13: =PROPER(B13) -> Brian Lopez | D13: =TRIM(C13) -> Brian Lopez | E13: 28 | F13: Female | G13: East Krista | H13: New York | I13: USA | J13: Gold | K13: =IF(ISBLANK(J13),"UNKNOWN",J13) -> Gold | L13: =IF(Customer_Dim[[#This Row],[Age]]<25,"Youth", IF(Customer_Dim[[#This Row],[Age]]<=40,"Adult", IF(Customer_Dim[[#This Row],[Age]]<=60,"Middle-Aged","Senior"))) -> Adult
A14: CUST1012 | B14: Kenneth Lambert | C14: =PROPER(B14) -> Kenneth Lambert | D14: =TRIM(C14) -> Kenneth Lambert | E14: 55 | F14: Female | G14: North Kathryn | H14: Kansas | I14: USA | J14: Platinum | K14: =IF(ISBLANK(J14),"UNKNOWN",J14) -> Platinum | L14: =IF(Customer_Dim[[#This Row],[Age]]<25,"Youth", IF(Customer_Dim[[#This Row],[Age]]<=40,"Adult", IF(Customer_Dim[[#This Row],[Age]]<=60,"Middle-Aged","Senior"))) -> Middle-Aged
... A19: CUST1017 | B19: Adam Cruz | C19: =PROPER(B19) -> Adam Cruz | D19: =TRIM(C19) -> Adam Cruz | E19: 60 | F19: Female | G19: Brandonville | H19: Georgia | I19: USA | J19: Platinum | K19: =IF(ISBLANK(J19),"UNKNOWN",J19) -> Platinum | L19: =IF(Customer_Dim[[#This Row],[Age]]<25,"Youth", IF(Customer_Dim[[#This Row],[Age]]<=40,"Adult", IF(Customer_Dim[[#This Row],[Age]]<=60,"Middle-Aged","Senior"))) -> Middle-Aged
A20: CUST1018 | B20: Rhonda Moss | C20: =PROPER(B20) -> Rhonda Moss | D20: =TRIM(C20) -> Rhonda Moss | E20: 43 | F20: Male | G20: South William | H20: Kansas | I20: USA | K20: =IF(ISBLANK(J20),"UNKNOWN",J20) -> UNKNOWN | L20: =IF(Customer_Dim[[#This Row],[Age]]<25,"Youth", IF(Customer_Dim[[#This Row],[Age]]<=40,"Adult", IF(Customer_Dim[[#This Row],[Age]]<=60,"Middle-Aged","Senior"))) -> Middle-Aged
A21: CUST1019 | B21: Michael Torres | C21: =PROPER(B21) -> Michael Torres | D21: =TRIM(C21) -> Michael Torres | E21: 46 | F21: Female | G21: Gonzalezfort | H21: New Jersey | I21: USA | J21: Platinum | K21: =IF(ISBLANK(J21),"UNKNOWN",J21) -> Platinum | L21: =IF(Customer_Dim[[#This Row],[Age]]<25,"Youth", IF(Customer_Dim[[#This Row],[Age]]<=40,"Adult", IF(Customer_Dim[[#This Row],[Age]]<=60,"Middle-Aged","Senior"))) -> Middle-Aged
A22: CUST1020 | B22: Bridget Allen | C22: =PROPER(B22) -> Bridget Allen | D22: =TRIM(C22) -> Bridget Allen | E22: 59 | F22: Male | G22: Lake Shaneburgh | H22: Delaware | I22: USA | J22: Silver | K22: =IF(ISBLANK(J22),"UNKNOWN",J22) -> Silver | L22: =IF(Customer_Dim[[#This Row],[Age]]<25,"Youth", IF(Customer_Dim[[#This Row],[Age]]<=40,"Adult", IF(Customer_Dim[[#This Row],[Age]]<=60,"Middle-Aged","Senior"))) -> Middle-Aged
A23: CUST1021 | B23: Jeff Martinez | C23: =PROPER(B23) -> Jeff Martinez | D23: =TRIM(C23) -> Jeff Martinez | E23: 36 | F23: Female | G23: Smithburgh | H23: Oklahoma | I23: USA | J23: Gold | K23: =IF(ISBLANK(J23),"UNKNOWN",J23) -> Gold | L23: =IF(Customer_Dim[[#This Row],[Age]]<25,"Youth", IF(Customer_Dim[[#This Row],[Age]]<=40,"Adult", IF(Customer_Dim[[#This Row],[Age]]<=60,"Middle-Aged","Senior"))) -> Adult
A24: CUST1022 | B24: paul fox | C24: =PROPER(B24) -> Paul Fox | D24: =TRIM(C24) -> Paul Fox | E24: 33 | F24: Female | G24: Michaelton | H24: Hawaii | I24: USA | J24: Silver | K24: =IF(ISBLANK(J24),"UNKNOWN",J24) -> Silver | L24: =IF(Customer_Dim[[#This Row],[Age]]<25,"Youth", IF(Customer_Dim[[#This Row],[Age]]<=40,"Adult", IF(Customer_Dim[[#This Row],[Age]]<=60,"Middle-Aged","Senior"))) -> Adult
A25: CUST1023 | B25: Jonathan Steele | C25: =PROPER(B25) -> Jonathan Steele | D25: =TRIM(C25) -> Jonathan Steele | E25: 52 | F25: Female | G25: Molinabury | H25: Oregon | I25: USA | J25: Silver | K25: =IF(ISBLANK(J25),"UNKNOWN",J25) -> Silver | L25: =IF(Customer_Dim[[#This Row],[Age]]<25,"Youth", IF(Customer_Dim[[#This Row],[Age]]<=40,"Adult", IF(Customer_Dim[[#This Row],[Age]]<=60,"Middle-Aged","Senior"))) -> Middle-Aged
A26: CUST1024 | B26: Heather Collins | C26: =PROPER(B26) -> Heather Collins | D26: =TRIM(C26) -> Heather Collins | E26: 40 | F26: Male | G26: Rogerschester | H26: Idaho | I26: USA | J26: Platinum | K26: =IF(ISBLANK(J26),"UNKNOWN",J26) -> Platinum | L26: =IF(Customer_Dim[[#This Row],[Age]]<25,"Youth", IF(Customer_Dim[[#This Row],[Age]]<=40,"Adult", IF(Customer_Dim[[#This Row],[Age]]<=60,"Middle-Aged","Senior"))) -> Adult
A27: CUST1025 | B27: Diana Taylor | C27: =PROPER(B27) -> Diana Taylor | D27: =TRIM(C27) -> Diana Taylor | E27: 59 | F27: Female | G27: Vasqueztown | H27: California | I27: USA | J27: Bronze | K27: =IF(ISBLANK(J27),"UNKNOWN",J27) -> Bronze | L27: =IF(Customer_Dim[[#This Row],[Age]]<25,"Youth", IF(Customer_Dim[[#This Row],[Age]]<=40,"Adult", IF(Customer_Dim[[#This Row],[Age]]<=60,"Middle-Aged","Senior"))) -> Middle-Aged
A28: CUST1026 | B28: Amber Carlson | C28: =PROPER(B28) -> Amber Carlson | D28: =TRIM(C28) -> Amber Carlson | E28: 18 | F28: Female | G28: East Michellemouth | H28: Missouri | I28: USA | J28: Gold | K28: =IF(ISBLANK(J28),"UNKNOWN",J28) -> Gold | L28: =IF(Customer_Dim[[#This Row],[Age]]<25,"Youth", IF(Customer_Dim[[#This Row],[Age]]<=40,"Adult", IF(Customer_Dim[[#This Row],[Age]]<=60,"Middle-Aged","Senior"))) -> Youth
A29: CUST1027 | B29: Leslie Johnson | C29: =PROPER(B29) -> Leslie Johnson | D29: =TRIM(C29) -> Leslie Johnson | E29: 31 | F29: Male | G29: Mollyshire | H29: Utah | I29: USA | K29: =IF(ISBLANK(J29),"UNKNOWN",J29) -> UNKNOWN | L29: =IF(Customer_Dim[[#This Row],[Age]]<25,"Youth", IF(Customer_Dim[[#This Row],[Age]]<=40,"Adult", IF(Customer_Dim[[#This Row],[Age]]<=60,"Middle-Aged","Senior"))) -> Adult
A30: CUST1028 | B30: Joshua Ryan | C30: =PROPER(B30) -> Joshua Ryan | D30: =TRIM(C30) -> Joshua Ryan | E30: 27 | F30: Female | G30: New David | H30: New Jersey | I30: USA | J30: Platinum | K30: =IF(ISBLANK(J30),"UNKNOWN",J30) -> Platinum | L30: =IF(Customer_Dim[[#This Row],[Age]]<25,"Youth", IF(Customer_Dim[[#This Row],[Age]]<=40,"Adult", IF(Customer_Dim[[#This Row],[Age]]<=60,"Middle-Aged","Senior"))) -> Adult
A31: CUST1029 | B31: David Arnold | C31: =PROPER(B31) -> David Arnold | D31: =TRIM(C31) -> David Arnold | E31: 54 | F31: Female | G31: East Jennifer | H31: California | I31: USA | J31: Silver | K31: =IF(ISBLANK(J31),"UNKNOWN",J31) -> Silver | L31: =IF(Customer_Dim[[#This Row],[Age]]<25,"Youth", IF(Customer_Dim[[#This Row],[Age]]<=40,"Adult", IF(Customer_Dim[[#This Row],[Age]]<=60,"Middle-Aged","Senior"))) -> Middle-Aged
A32: CUST1030 | B32: Jessica Acevedo | C32: =PROPER(B32) -> Jessica Acevedo | D32: =TRIM(C32) -> Jessica Acevedo | E32: 64 | F32: Female | G32: Amybury | H32: Pennsylvania | I32: USA | J32: Bronze | K32: =IF(ISBLANK(J32),"UNKNOWN",J32) -> Bronze | L32: =IF(Customer_Dim[[#This Row],[Age]]<25,"Youth", IF(Customer_Dim[[#This Row],[Age]]<=40,"Adult", IF(Customer_Dim[[#This Row],[Age]]<=60,"Middle-Aged","Senior"))) -> Senior
A33: CUST1031 | B33: Sarah Vance | C33: =PROPER(B33) -> Sarah Vance | D33: =TRIM(C33) -> Sarah Vance | E33: 41 | F33: Male | G33: Johnsonville | H33: Oregon | I33: USA | J33: Silver | K33: =IF(ISBLANK(J33),"UNKNOWN",J33) -> Silver | L33: =IF(Customer_Dim[[#This Row],[Age]]<25,"Youth", IF(Customer_Dim[[#This Row],[Age]]<=40,"Adult", IF(Customer_Dim[[#This Row],[Age]]<=60,"Middle-Aged","Senior"))) -> Middle-Aged
A34: CUST1032 | B34: Mike Jennings | C34: =PROPER(B34) -> Mike Jennings | D34: =TRIM(C34) -> Mike Jennings | E34: 48 | F34: Female | G34: Fostermouth | H34: Arizona | I34: USA | J34: Gold | K34: =IF(ISBLANK(J34),"UNKNOWN",J34) -> Gold | L34: =IF(Customer_Dim[[#This Row],[Age]]<25,"Youth", IF(Customer_Dim[[#This Row],[Age]]<=40,"Adult", IF(Customer_Dim[[#This Row],[Age]]<=60,"Middle-Aged","Senior"))) -> Middle-Aged
A35: CUST1033 | B35: Robert Jones DDS | C35: =PROPER(B35) -> Robert Jones Dds | D35: =TRIM(C35) -> Robert Jones Dds | E35: 25 | F35: Male | G35: Tristanton | H35: Oklahoma | I35: USA | J35: Platinum | K35: =IF(ISBLANK(J35),"UNKNOWN",J35) -> Platinum | L35: =IF(Customer_Dim[[#This Row],[Age]]<25,"Youth", IF(Customer_Dim[[#This Row],[Age]]<=40,"Adult", IF(Customer_Dim[[#This Row],[Age]]<=60,"Middle-Aged","Senior"))) -> Adult
A36: CUST1034 | B36: Christopher Olson | C36: =PROPER(B36) -> Christopher Olson | D36: =TRIM(C36) -> Christopher Olson | E36: 27 | F36: Female | G36: West Richard | H36: Maryland | I36: USA | J36: Platinum | K36: =IF(ISBLANK(J36),"UNKNOWN",J36) -> Platinum | L36: =IF(Customer_Dim[[#This Row],[Age]]<25,"Youth", IF(Customer_Dim[[#This Row],[Age]]<=40,"Adult", IF(Customer_Dim[[#This Row],[Age]]<=60,"Middle-Aged","Senior"))) -> Adult
A37: CUST1035 | B37: Rachel Myers | C37: =PROPER(B37) -> Rachel Myers | D37: =TRIM(C37) -> Rachel Myers | E37: 52 | F37: Male | G37: Robertberg | H37: North Dakota | I37: USA | J37: Silver | K37: =IF(ISBLANK(J37),"UNKNOWN",J37) -> Silver | L37: =IF(Customer_Dim[[#This Row],[Age]]<25,"Youth", IF(Customer_Dim[[#This Row],[Age]]<=40,"Adult", IF(Customer_Dim[[#This Row],[Age]]<=60,"Middle-Aged","Senior"))) -> Middle-Aged
A38: CUST1036 | B38: Thomas Phillips | C38: =PROPER(B38) -> Thomas Phillips | D38: =TRIM(C38) -> Thomas Phillips | E38: 20 | F38: Female | G38: Luisfurt | H38: Georgia | I38: USA | J38: Gold | K38: =IF(ISBLANK(J38),"UNKNOWN",J38) -> Gold | L38: =IF(Customer_Dim[[#This Row],[Age]]<25,"Youth", IF(Customer_Dim[[#This Row],[Age]]<=40,"Adult", IF(Customer_Dim[[#This Row],[Age]]<=60,"Middle-Aged","Senior"))) -> Youth
A39: CUST1037 | B39: Christopher Carter | C39: =PROPER(B39) -> Christopher Carter | D39: =TRIM(C39) -> Christopher Carter | E39: 27 | F39: Female | G39: Brendastad | H39: South Dakota | I39: USA | K39: =IF(ISBLANK(J39),"UNKNOWN",J39) -> UNKNOWN | L39: =IF(Customer_Dim[[#This Row],[Age]]<25,"Youth", IF(Customer_Dim[[#This Row],[Age]]<=40,"Adult", IF(Customer_Dim[[#This Row],[Age]]<=60,"Middle-Aged","Senior"))) -> Adult
A40: CUST1038 | B40: Deanna Simpson | C40: =PROPER(B40) -> Deanna Simpson | D40: =TRIM(C40) -> Deanna Simpson | E40: 35 | F40: Female | G40: Brownport | H40: North Dakota | I40: USA | J40: Bronze | K40: =IF(ISBLANK(J40),"UNKNOWN",J40) -> Bronze | L40: =IF(Customer_Dim[[#This Row],[Age]]<25,"Youth", IF(Customer_Dim[[#This Row],[Age]]<=40,"Adult", IF(Customer_Dim[[#This Row],[Age]]<=60,"Middle-Aged","Senior"))) -> Adult
A41: CUST1039 | B41: Tonya Reynolds | C41: =PROPER(B41) -> Tonya Reynolds | D41: =TRIM(C41) -> Tonya Reynolds | E41: 55 | F41: Female | G41: Darleneton | H41: Michigan | I41: USA | J41: Gold | K41: =IF(ISBLANK(J41),"UNKNOWN",J41) -> Gold | L41: =IF(Customer_Dim[[#This Row],[Age]]<25,"Youth", IF(Customer_Dim[[#This Row],[Age]]<=40,"Adult", IF(Customer_Dim[[#This Row],[Age]]<=60,"Middle-Aged","Senior"))) -> Middle-Aged
A42: CUST1040 | B42: Eric Vega | C42: =PROPER(B42) -> Eric Vega | D42: =TRIM(C42) -> Eric Vega | E42: 50 | F42: Male | G42: Williamsonland | H42: Kansas | I42: USA | J42: Gold | K42: =IF(ISBLANK(J42),"UNKNOWN",J42) -> Gold | L42: =IF(Customer_Dim[[#This Row],[Age]]<25,"Youth", IF(Customer_Dim[[#This Row],[Age]]<=40,"Adult", IF(Customer_Dim[[#This Row],[Age]]<=60,"Middle-Aged","Senior"))) -> Middle-Aged
A43: CUST1041 | B43: James Gibbs | C43: =PROPER(B43) -> James Gibbs | D43: =TRIM(C43) -> James Gibbs | E43: 21 | F43: Male | G43: Mooneyshire | H43: Alaska | I43: USA | J43: Platinum | K43: =IF(ISBLANK(J43),"UNKNOWN",J43) -> Platinum | L43: =IF(Customer_Dim[[#This Row],[Age]]<25,"Youth", IF(Customer_Dim[[#This Row],[Age]]<=40,"Adult", IF(Customer_Dim[[#This Row],[Age]]<=60,"Middle-Aged","Senior"))) -> Youth
A44: CUST1042 | B44: William Martin | C44: =PROPER(B44) -> William Martin | D44: =TRIM(C44) -> William Martin | E44: 19 | F44: Male | G44: Ryanburgh | H44: Connecticut | I44: USA | J44: Platinum | K44: =IF(ISBLANK(J44),"UNKNOWN",J44) -> Platinum | L44: =IF(Customer_Dim[[#This Row],[Age]]<25,"Youth", IF(Customer_Dim[[#This Row],[Age]]<=40,"Adult", IF(Customer_Dim[[#This Row],[Age]]<=60,"Middle-Aged","Senior"))) -> Youth
...

Sheet Product_Dim
A1: Product_ID | B1: Product_Name | C1: Category | D1: Sub_Category | E1: Brand | F1: Cost | G1: COST2 | H1: Stock | I1: Stock3
A2: PROD0 | B2: Brother Laser Printer | C2: Electronics | D2: Computer | E2: Hunt Inc | F2: 112.42 | G2: =IF(ISBLANK(F2),AVERAGE($F$2:$F$101),F2) -> 112.42 | H2: 416 | I2: =IF(ISBLANK(H2),MODE($H$2:$H$101),H2) -> 416
A3: PROD1 | B3: Men's Graphic T-Shirt | C3: Clothing | D3: Tops | E3: Terry-Moore | F3: 342.56 | G3: =IF(ISBLANK(F3),AVERAGE($F$2:$F$101),F3) -> 342.56 | H3: 181 | I3: =IF(ISBLANK(H3),MODE($H$2:$H$101),H3) -> 181
A4: PROD2 | B4: Women's Casual Hoodie | C4: Clothing | D4: Outerwear | E4: Sims Inc | G4: =IF(ISBLANK(F4),AVERAGE($F$2:$F$101),F4) -> 254.04362 | H4: 352 | I4: =IF(ISBLANK(H4),MODE($H$2:$H$101),H4) -> 352
A5: P-3 | B5: Men's Running Jacket | C5: Clothing | D5: Outerwear | E5: Pineda Ltd | F5: 364.67 | G5: =IF(ISBLANK(F5),AVERAGE($F$2:$F$101),F5) -> 364.67 | H5: 452 | I5: =IF(ISBLANK(H5),MODE($H$2:$H$101),H5) -> 452
A6: PROD4 | B6: Women's Yoga Pants | C6: Clothing | D6: Bottoms | E6: Gonzales-Davis | F6: 306.46 | G6: =IF(ISBLANK(F6),AVERAGE($F$2:$F$101),F6) -> 306.46 | H6: 487 | I6: =IF(ISBLANK(H6),MODE($H$2:$H$101),H6) -> 487
A7: PROD5 | B7: Men's Leather Belt | C7: Clothing | D7: Accessories | E7: Baldwin, Garza and Gonzalez | F7: 261 | G7: =IF(ISBLANK(F7),AVERAGE($F$2:$F$101),F7) -> 261 | H7: 59 | I7: =IF(ISBLANK(H7),MODE($H$2:$H$101),H7) -> 59
A8: PROD6 | B8: Herbal Face Moisturizer | C8: Beauty | D8: Skincare | E8: Davidson PLC | F8: 312.8 | G8: =IF(ISBLANK(F8),AVERAGE($F$2:$F$101),F8) -> 312.8 | H8: 350 | I8: =IF(ISBLANK(H8),MODE($H$2:$H$101),H8) -> 350
A9: PROD7 | B9: LED Table Lamp | C9: Home | D9: Lighting | E9: Harrell LLC | F9: 218.86 | G9: =IF(ISBLANK(F9),AVERAGE($F$2:$F$101),F9) -> 218.86 | H9: 170 | I9: =IF(ISBLANK(H9),MODE($H$2:$H$101),H9) -> 170
A10: PROD8 | B10: Wireless Bluetooth Earbuds | C10: Electronics | D10: Audio | E10: Perez-Johnston | F10: 439.07 | G10: =IF(ISBLANK(F10),AVERAGE($F$2:$F$101),F10) -> 439.07 | H10: 142 | I10: =IF(ISBLANK(H10),MODE($H$2:$H$101),H10) -> 142
A11: PROD9 | B11: Adjustable Dumbbell Set | C11: Sports | D11: Fitness | E11: Hill PLC | F11: 495.72 | G11: =IF(ISBLANK(F11),AVERAGE($F$2:$F$101),F11) -> 495.72 | H11: 323 | I11: =IF(ISBLANK(H11),MODE($H$2:$H$101),H11) -> 323
A12: PROD10 | B12: Ceramic Kitchen Bowl Set | C12: Home | D12: Kitchen | E12: Hamilton Group | F12: 298.86 | G12: =IF(ISBLANK(F12),AVERAGE($F$2:$F$101),F12) -> 298.86 | H12: 308 | I12: =IF(ISBLANK(H12),MODE($H$2:$H$101),H12) -> 308
A13: PROD11 | B13: HD Smart TV Stick | C13: Electronics | D13: Accessories | E13: Gibson, Hobbs and Weaver | F13: 449.4 | G13: =IF(ISBLANK(F13),AVERAGE($F$2:$F$101),F13) -> 449.4 | I13: =IF(ISBLANK(H13),MODE($H$2:$H$101),H13) -> 82
A14: PROD12 | B14: Hair Strengthening Shampoo | C14: Beauty | D14: Haircare | E14: Rice LLC | F14: 115.82 | G14: =IF(ISBLANK(F14),AVERAGE($F$2:$F$101),F14) -> 115.82 | H14: 460 | I14: =IF(ISBLANK(H14),MODE($H$2:$H$101),H14) -> 460
A15: PROD13 | B15: USB-C Fast Charger | C15: Electronics | D15: Accessories | E15: Dawson-Perkins | F15: 242.23 | G15: =IF(ISBLANK(F15),AVERAGE($F$2:$F$101),F15) -> 242.23 | H15: 453 | I15: =IF(ISBLANK(H15),MODE($H$2:$H$101),H15) -> 453
A16: PROD14 | B16: Decorative Wall Mirror | C16: Home | D16: Decor | E16: Luna, Anderson and Bowman | F16: 48.01 | G16: =IF(ISBLANK(F16),AVERAGE($F$2:$F$101),F16) -> 48.01 | H16: 439 | I16: =IF(ISBLANK(H16),MODE($H$2:$H$101),H16) -> 439
A17: PROD15 | B17: 4K Home Projector | C17: Electronics | D17: Appliances | E17: Thomas LLC | F17: 465.34 | G17: =IF(ISBLANK(F17),AVERAGE($F$2:$F$101),F17) -> 465.34 | H17: 301 | I17: =IF(ISBLANK(H17),MODE($H$2:$H$101),H17) -> 301
A18: P-16 | B18: Beard Grooming Kit | C18: Beauty | D18: Grooming | E18: Erickson-Green | F18: 337.42 | G18: =IF(ISBLANK(F18),AVERAGE($F$2:$F$101),F18) -> 337.42 | H18: 256 | I18: =IF(ISBLANK(H18),MODE($H$2:$H$101),H18) -> 256
A19: PROD17 | B19: Soccer Training Cone Set | C19: Sports | D19: Accessories | E19: Ford, Murphy and Wilson | F19: 144.53 | G19: =IF(ISBLANK(F19),AVERAGE($F$2:$F$101),F19) -> 144.53 | H19: 367 | I19: =IF(ISBLANK(H19),MODE($H$2:$H$101),H19) -> 367
A20: PROD18 | B20: Women's Denim Jeans | C20: Clothing | D20: Bottoms | E20: Guerra-Hendrix | G20: =IF(ISBLANK(F20),AVERAGE($F$2:$F$101),F20) -> 254.04362 | H20: 343 | I20: =IF(ISBLANK(H20),MODE($H$2:$H$101),H20) -> 343
A21: PROD19 | B21: Knee Support Brace | C21: Sports | D21: Equipment | E21: May-Reese | F21: 21.34 | G21: =IF(ISBLANK(F21),AVERAGE($F$2:$F$101),F21) -> 21.34 | H21: 65 | I21: =IF(ISBLANK(H21),MODE($H$2:$H$101),H21) -> 65
A22: PROD20 | B22: Outdoor Sports Water Bottle | C22: Sports | D22: Accessories | E22: Soto-Ellis | F22: 131.51 | G22: =IF(ISBLANK(F22),AVERAGE($F$2:$F$101),F22) -> 131.51 | I22: =IF(ISBLANK(H22),MODE($H$2:$H$101),H22) -> 82
A23: PROD21 | B23: Multi-Purpose Storage Box | C23: Home | D23: Storage | E23: Gardner-Montes | F23: 123.46 | G23: =IF(ISBLANK(F23),AVERAGE($F$2:$F$101),F23) -> 123.46 | H23: 76 | I23: =IF(ISBLANK(H23),MODE($H$2:$H$101),H23) -> 76
A24: PROD22 | B24: Carbon Fiber Tennis Racket | C24: Sports | D24: Equipment | E24: Flores, Pineda and Rodriguez | F24: 484.62 | G24: =IF(ISBLANK(F24),AVERAGE($F$2:$F$101),F24) -> 484.62 | H24: 432 | I24: =IF(ISBLANK(H24),MODE($H$2:$H$101),H24) -> 432
A25: PROD23 | B25: Men's Formal Shirt | C25: Clothing | D25: Tops | E25: Moon, Mora and Santos | G25: =IF(ISBLANK(F25),AVERAGE($F$2:$F$101),F25) -> 254.04362 | H25: 360 | I25: =IF(ISBLANK(H25),MODE($H$2:$H$101),H25) -> 360
A26: PROD24 | B26: Foldable Camping Chair | C26: Sports | D26: Outdoor | E26: Cook Ltd | F26: 166.06 | G26: =IF(ISBLANK(F26),AVERAGE($F$2:$F$101),F26) -> 166.06 | H26: 340 | I26: =IF(ISBLANK(H26),MODE($H$2:$H$101),H26) -> 340
A27: PROD25 | B27: Women's Scarf Set | C27: Clothing | D27: Accessories | E27: Brown and Sons | F27: 174.02 | G27: =IF(ISBLANK(F27),AVERAGE($F$2:$F$101),F27) -> 174.02 | H27: 268 | I27: =IF(ISBLANK(H27),MODE($H$2:$H$101),H27) -> 268
A28: PROD26 | B28: Wireless Bluetooth Speaker | C28: Electronics | D28: Audio | E28: Reed-Schmidt | F28: 322.41 | G28: =IF(ISBLANK(F28),AVERAGE($F$2:$F$101),F28) -> 322.41 | H28: 213 | I28: =IF(ISBLANK(H28),MODE($H$2:$H$101),H28) -> 213
A29: PROD27 | B29: Decorative Floor Vase | C29: Home | D29: Decor | E29: Khan, Jones and Paul | G29: =IF(ISBLANK(F29),AVERAGE($F$2:$F$101),F29) -> 254.04362 | H29: 378 | I29: =IF(ISBLANK(H29),MODE($H$2:$H$101),H29) -> 378
A30: PROD28 | B30: Sports Stopwatch Timer | C30: Sports | D30: Accessories | E30: Burns-Hansen | F30: 38.76 | G30: =IF(ISBLANK(F30),AVERAGE($F$2:$F$101),F30) -> 38.76 | H30: 137 | I30: =IF(ISBLANK(H30),MODE($H$2:$H$101),H30) -> 137
A31: PROD29 | B31: Fabric Sofa Throw Blanket | C31: Home | D31: Decor | E31: Hoffman Group | F31: 218.48 | G31: =IF(ISBLANK(F31),AVERAGE($F$2:$F$101),F31) -> 218.48 | H31: 276 | I31: =IF(ISBLANK(H31),MODE($H$2:$H$101),H31) -> 276
A32: PROD30 | B32: Stainless Steel Cutlery Set | C32: Home | D32: Kitchen | E32: Stevens, Fernandez and Martin | F32: 19.52 | G32: =IF(ISBLANK(F32),AVERAGE($F$2:$F$101),F32) -> 19.52 | H32: 57 | I32: =IF(ISBLANK(H32),MODE($H$2:$H$101),H32) -> 57
A33: PROD31 | B33: Basketball | C33: Sports | D33: Team Sports | E33: Nolan-Snow | F33: 204.39 | G33: =IF(ISBLANK(F33),AVERAGE($F$2:$F$101),F33) -> 204.39 | H33: 281 | I33: =IF(ISBLANK(H33),MODE($H$2:$H$101),H33) -> 281
A34: PROD32 | B34: Vitamin C Face Serum | C34: Beauty | D34: Skincare | E34: Griffin Ltd | F34: 283.83 | G34: =IF(ISBLANK(F34),AVERAGE($F$2:$F$101),F34) -> 283.83 | H34: 244 | I34: =IF(ISBLANK(H34),MODE($H$2:$H$101),H34) -> 244
A35: PROD33 | B35: Modern Wall Clock | C35: Home | D35: Decor | E35: Weiss-Watson | F35: 179.77 | G35: =IF(ISBLANK(F35),AVERAGE($F$2:$F$101),F35) -> 179.77 | H35: 305 | I35: =IF(ISBLANK(H35),MODE($H$2:$H$101),H35) -> 305
A36: PROD34 | B36: Gaming Mechanical Keyboard | C36: Electronics | D36: Computer | E36: Lucero LLC | F36: 419.28 | G36: =IF(ISBLANK(F36),AVERAGE($F$2:$F$101),F36) -> 419.28 | H36: 86 | I36: =IF(ISBLANK(H36),MODE($H$2:$H$101),H36) -> 86
A37: PROD35 | B37: Bedroom Table Lamp | C37: Home | D37: Lighting | E37: Jones LLC | F37: 382.22 | G37: =IF(ISBLANK(F37),AVERAGE($F$2:$F$101),F37) -> 382.22 | H37: 329 | I37: =IF(ISBLANK(H37),MODE($H$2:$H$101),H37) -> 329
A38: PROD36 | B38: Women's Summer Dress | C38: Clothing | D38: Tops | E38: Smith-Mills | F38: 223.43 | G38: =IF(ISBLANK(F38),AVERAGE($F$2:$F$101),F38) -> 223.43 | H38: 154 | I38: =IF(ISBLANK(H38),MODE($H$2:$H$101),H38) -> 154
A39: PROD37 | B39: Men's Casual Sneakers | C39: Clothing | D39: Footwear | E39: Hogan-Lee | F39: 353.47 | G39: =IF(ISBLANK(F39),AVERAGE($F$2:$F$101),F39) -> 353.47 | H39: 214 | I39: =IF(ISBLANK(H39),MODE($H$2:$H$101),H39) -> 214
A40: PROD38 | B40: Sports Water Hydration Pack | C40: Sports | D40: Outdoor | E40: Sims-Smith | F40: 135.61 | G40: =IF(ISBLANK(F40),AVERAGE($F$2:$F$101),F40) -> 135.61 | H40: 394 | I40: =IF(ISBLANK(H40),MODE($H$2:$H$101),H40) -> 394
...

Sheet Store_Dim
A1: Store_ID | B1: Store_Name | C1: Region | D1: City | E1: Store_Type
A2: STORE0 | B2: Rivera-Warner | C2: East | D2: Washingtonfurt | E2: Flagship
A3: STORE1 | B3: Martinez, Adkins and Johnson | C3: North | D3: Danielmouth | E3: Flagship
A4: STORE2 | B4: Black-Horn | C4: South | D4: North Nancyview | E4: Outlet
A5: STORE3 | B5: Johnson-Wright | C5: North | D5: Hoodberg | E5: Outlet
A6: STORE4 | B6: Alexander Group | C6: South | D6: Port Sharon | E6: Online
A7: STORE5 | B7: Gray Ltd | C7: North | D7: New Michaelchester | E7: Outlet
A8: STORE6 | B8: Benson-Elliott | C8: East | D8: Port Josephberg | E8: Online
A9: STORE7 | B9: Martinez-Mullins | C9: South | D9: Williamsfurt | E9: Online
A10: STORE8 | B10: Bean, Jones and Park | C10: West | D10: Thompsonborough | E10: Online
A11: STORE9 | B11: Moore, Padilla and Butler | C11: South | D11: East Johnstad | E11: Flagship
A12: STORE10 | B12: Hill, Wagner and Ballard | C12: East | D12: East Davidville | E12: Online
... A21: STORE19 | B21: Mann-Austin | C21: East | D21: Vasquezborough | E21: Online

Sheet Sheet9
A3: Row Labels | B3: Sum of Total Amount
A4: STORE0 | B4: 85138.555
A5: STORE1 | B5: 100344.57
A6: STORE10 | B6: 109791.72
A7: STORE11 | B7: 93048.141
A8: STORE12 | B8: 116829.22
A9: STORE13 | B9: 114592.72
A10: STORE14 | B10: 106248.28
A11: STORE15 | B11: 99679.086
A12: STORE16 | B12: 111704.94
A13: STORE17 | B13: 121555.11
A14: STORE18 | B14: 105447.24
A15: STORE19 | B15: 94225.723
... A24: Grand Total | B24: 2173363.4

Sheet Sales_Fact
A1: Sales_ID | B1: Order_Date | C1: Customer_ID | D1: Product_ID | E1: Store_ID | F1: Quantity | G1: Quantity1 | H1: Unit_Price | I1: UNIT Price | J1: Discount | K1: Discount2 | L1: Payment_Type | M1: Total_Amount | N1: Total Amount | O1: Loyalty Level | P1: Age | Q1: Gender | R1: Product category
A2: SALE0 | B2: 45480 | C2: CUST1409 | D2: PROD97 | E2: =TRIM(Sales_fact[[#This Row],[Store_ID]]) -> STORE3 | F2: 1 | G2: =IF(ISBLANK(F2),MODE($F$2:$F$2001),F2) -> 1 | H2: 218.04 | I2: =IF(ISBLANK(H2),AVERAGE($H$2:$H$2001),H2) -> 218.04 | J2: 0.09 | K2: =IF(ISBLANK(J2),MODE($J$2:$J$2001),J2) -> 0.09 | L2: Credit Card | M2: 198.4164 | N2: =G2*I2*(1-K2) -> 198.4164 | O2: =_xlfn.XLOOKUP(Sales_fact[[#This Row],[Customer_ID]],'Customer_Dim'!A:A,'Customer_Dim'!K:K,"Not Found") -> Gold | P2: =_xlfn.XLOOKUP(Sales_fact[[#This Row],[Customer_ID]],'Customer_Dim'!A:A, 'Customer_Dim'!E:E, "Not Found") -> 55 | Q2: =VLOOKUP(Sales_fact[[#This Row],[Customer_ID]], 'Customer_Dim'!A:F, 6, FALSE) -> Male | R2: =_xlfn.XLOOKUP(Sales_fact[[#This Row],[Product_ID]],Product_Dim!A:A,Product_Dim!C:C,"OTHERS") -> Sports | T2: Column1
A3: SALE1 | B3: 45285 | C3: CUST1467 | D3: PROD74 | E3: =TRIM(Sales_fact[[#This Row],[Store_ID]]) -> STORE17 | F3: 3 | G3: =IF(ISBLANK(F3),MODE($F$2:$F$2001),F3) -> 3 | H3: 104.47 | I3: =IF(ISBLANK(H3),AVERAGE($H$2:$H$2001),H3) -> 104.47 | J3: 0.27 | K3: =IF(ISBLANK(J3),MODE($J$2:$J$2001),J3) -> 0.27 | L3: PayPal | M3: 228.7893 | N3: =G3*I3*(1-K3) -> 228.7893 | O3: =_xlfn.XLOOKUP(Sales_fact[[#This Row],[Customer_ID]],'Customer_Dim'!A:A,'Customer_Dim'!K:K,"Not Found") -> Gold | P3: =_xlfn.XLOOKUP(Sales_fact[[#This Row],[Customer_ID]],'Customer_Dim'!A:A, 'Customer_Dim'!E:E, "Not Found") -> 63 | Q3: =VLOOKUP(Sales_fact[[#This Row],[Customer_ID]], 'Customer_Dim'!A:F, 6, FALSE) -> Female | R3: =_xlfn.XLOOKUP(Sales_fact[[#This Row],[Product_ID]],Product_Dim!A:A,Product_Dim!C:C,"OTHERS") -> Electronics
A4: SALE2 | B4: 45446 | C4: CUST1056 | D4: PROD49 | E4: =TRIM(Sales_fact[[#This Row],[Store_ID]]) -> STORE8 | F4: 4 | G4: =IF(ISBLANK(F4),MODE($F$2:$F$2001),F4) -> 4 | H4: 914.05 | I4: =IF(ISBLANK(H4),AVERAGE($H$2:$H$2001),H4) -> 914.05 | J4: 0.25 | K4: =IF(ISBLANK(J4),MODE($J$2:$J$2001),J4) -> 0.25 | L4: Credit Card | M4: 2742.15 | N4: =G4*I4*(1-K4) -> 2742.15 | O4: =_xlfn.XLOOKUP(Sales_fact[[#This Row],[Customer_ID]],'Customer_Dim'!A:A,'Customer_Dim'!K:K,"Not Found") -> Gold | P4: =_xlfn.XLOOKUP(Sales_fact[[#This Row],[Customer_ID]],'Customer_Dim'!A:A, 'Customer_Dim'!E:E, "Not Found") -> 49 | Q4: =VLOOKUP(Sales_fact[[#This Row],[Customer_ID]], 'Customer_Dim'!A:F, 6, FALSE) -> Female | R4: =_xlfn.XLOOKUP(Sales_fact[[#This Row],[Product_ID]],Product_Dim!A:A,Product_Dim!C:C,"OTHERS") -> Beauty | T4: Mean | U4: 1086.6817
A5: SALE3 | B5: 45259 | C5: CUST1346 | D5: PROD76 | E5: =TRIM(Sales_fact[[#This Row],[Store_ID]]) -> STORE8 | F5: 1 | G5: =IF(ISBLANK(F5),MODE($F$2:$F$2001),F5) -> 1 | H5: 921.51 | I5: =IF(ISBLANK(H5),AVERAGE($H$2:$H$2001),H5) -> 921.51 | J5: 0.16 | K5: =IF(ISBLANK(J5),MODE($J$2:$J$2001),J5) -> 0.16 | L5: COD | M5: 774.0684 | N5: =G5*I5*(1-K5) -> 774.0684 | O5: =_xlfn.XLOOKUP(Sales_fact[[#This Row],[Customer_ID]],'Customer_Dim'!A:A,'Customer_Dim'!K:K,"Not Found") -> Platinum | P5: =_xlfn.XLOOKUP(Sales_fact[[#This Row],[Customer_ID]],'Customer_Dim'!A:A, 'Customer_Dim'!E:E, "Not Found") -> 58 | Q5: =VLOOKUP(Sales_fact[[#This Row],[Customer_ID]], 'Customer_Dim'!A:F, 6, FALSE) -> Female | R5: =_xlfn.XLOOKUP(Sales_fact[[#This Row],[Product_ID]],Product_Dim!A:A,Product_Dim!C:C,"OTHERS") -> Electronics | T5: Standard Error | U5: 18.303306
A6: SALE4 | B6: 45297 | C6: CUST1493 | D6: PROD59 | E6: =TRIM(Sales_fact[[#This Row],[Store_ID]]) -> STORE5 | F6: 3 | G6: =IF(ISBLANK(F6),MODE($F$2:$F$2001),F6) -> 3 | H6: 745.3 | I6: =IF(ISBLANK(H6),AVERAGE($H$2:$H$2001),H6) -> 745.3 | J6: 0.18 | K6: =IF(ISBLANK(J6),MODE($J$2:$J$2001),J6) -> 0.18 | L6: Credit Card | M6: 1833.438 | N6: =G6*I6*(1-K6) -> 1833.438 | O6: =_xlfn.XLOOKUP(Sales_fact[[#This Row],[Customer_ID]],'Customer_Dim'!A:A,'Customer_Dim'!K:K,"Not Found") -> Silver | P6: =_xlfn.XLOOKUP(Sales_fact[[#This Row],[Customer_ID]],'Customer_Dim'!A:A, 'Customer_Dim'!E:E, "Not Found") -> 28 | Q6: =VLOOKUP(Sales_fact[[#This Row],[Customer_ID]], 'Customer_Dim'!A:F, 6, FALSE) -> Male | R6: =_xlfn.XLOOKUP(Sales_fact[[#This Row],[Product_ID]],Product_Dim!A:A,Product_Dim!C:C,"OTHERS") -> Beauty | T6: Median | U6: 868.7182
A7: SALE5 | B7: 45499 | C7: CUST1116 | D7: PROD15 | E7: =TRIM(Sales_fact[[#This Row],[Store_ID]]) -> STORE7 | F7: 3 | G7: =IF(ISBLANK(F7),MODE($F$2:$F$2001),F7) -> 3 | H7: 147.01 | I7: =IF(ISBLANK(H7),AVERAGE($H$2:$H$2001),H7) -> 147.01 | J7: 0.19 | K7: =IF(ISBLANK(J7),MODE($J$2:$J$2001),J7) -> 0.19 | L7: COD | M7: 357.2343 | N7: =G7*I7*(1-K7) -> 357.2343 | O7: =_xlfn.XLOOKUP(Sales_fact[[#This Row],[Customer_ID]],'Customer_Dim'!A:A,'Customer_Dim'!K:K,"Not Found") -> Platinum | P7: =_xlfn.XLOOKUP(Sales_fact[[#This Row],[Customer_ID]],'Customer_Dim'!A:A, 'Customer_Dim'!E:E, "Not Found") -> 18 | Q7: =VLOOKUP(Sales_fact[[#This Row],[Customer_ID]], 'Customer_Dim'!A:F, 6, FALSE) -> Female | R7: =_xlfn.XLOOKUP(Sales_fact[[#This Row],[Product_ID]],Product_Dim!A:A,Product_Dim!C:C,"OTHERS") -> Electronics | T7: Mode | U7: #N/A
A8: SALE6 | B8: 45850 | C8: CUST1016 | D8: PROD56 | E8: =TRIM(Sales_fact[[#This Row],[Store_ID]]) -> STORE4 | F8: 2 | G8: =IF(ISBLANK(F8),MODE($F$2:$F$2001),F8) -> 2 | H8: 785.31 | I8: =IF(ISBLANK(H8),AVERAGE($H$2:$H$2001),H8) -> 785.31 | J8: 0.15 | K8: =IF(ISBLANK(J8),MODE($J$2:$J$2001),J8) -> 0.15 | L8: PayPal | M8: 1335.027 | N8: =G8*I8*(1-K8) -> 1335.027 | O8: =_xlfn.XLOOKUP(Sales_fact[[#This Row],[Customer_ID]],'Customer_Dim'!A:A,'Customer_Dim'!K:K,"Not Found") -> Bronze | P8: =_xlfn.XLOOKUP(Sales_fact[[#This Row],[Customer_ID]],'Customer_Dim'!A:A, 'Customer_Dim'!E:E, "Not Found") -> 24 | Q8: =VLOOKUP(Sales_fact[[#This Row],[Customer_ID]], 'Customer_Dim'!A:F, 6, FALSE) -> Female | R8: =_xlfn.XLOOKUP(Sales_fact[[#This Row],[Product_ID]],Product_Dim!A:A,Product_Dim!C:C,"OTHERS") -> Home | T8: Standard Deviation | U8: 818.54871
A9: SALE7 | B9: 45248 | C9: CUST1152 | D9: PROD70 | E9: =TRIM(Sales_fact[[#This Row],[Store_ID]]) -> STORE8 | F9: 4 | G9: =IF(ISBLANK(F9),MODE($F$2:$F$2001),F9) -> 4 | H9: 342.39 | I9: =IF(ISBLANK(H9),AVERAGE($H$2:$H$2001),H9) -> 342.39 | J9: 0.23 | K9: =IF(ISBLANK(J9),MODE($J$2:$J$2001),J9) -> 0.23 | L9: PayPal | M9: 1054.5612 | N9: =G9*I9*(1-K9) -> 1054.5612 | O9: =_xlfn.XLOOKUP(Sales_fact[[#This Row],[Customer_ID]],'Customer_Dim'!A:A,'Customer_Dim'!K:K,"Not Found") -> Platinum | P9: =_xlfn.XLOOKUP(Sales_fact[[#This Row],[Customer_ID]],'Customer_Dim'!A:A, 'Customer_Dim'!E:E, "Not Found") -> 41 | Q9: =VLOOKUP(Sales_fact[[#This Row],[Customer_ID]], 'Customer_Dim'!A:F, 6, FALSE) -> Female | R9: =_xlfn.XLOOKUP(Sales_fact[[#This Row],[Product_ID]],Product_Dim!A:A,Product_Dim!C:C,"OTHERS") -> Home | T9: Sample Variance | U9: 670021.99
A10: SALE8 | B10: 45781 | C10: CUST1187 | D10: PROD99 | E10: =TRIM(Sales_fact[[#This Row],[Store_ID]]) -> STORE5 | G10: =IF(ISBLANK(F10),MODE($F$2:$F$2001),F10) -> 2 | H10: 448.25 | I10: =IF(ISBLANK(H10),AVERAGE($H$2:$H$2001),H10) -> 448.25 | J10: 0.07 | K10: =IF(ISBLANK(J10),MODE($J$2:$J$2001),J10) -> 0.07 | L10: PayPal | M10: 1250.6175 | N10: =G10*I10*(1-K10) -> 833.745 | O10: =_xlfn.XLOOKUP(Sales_fact[[#This Row],[Customer_ID]],'Customer_Dim'!A:A,'Customer_Dim'!K:K,"Not Found") -> Platinum | P10: =_xlfn.XLOOKUP(Sales_fact[[#This Row],[Customer_ID]],'Customer_Dim'!A:A, 'Customer_Dim'!E:E, "Not Found") -> 60 | Q10: =VLOOKUP(Sales_fact[[#This Row],[Customer_ID]], 'Customer_Dim'!A:F, 6, FALSE) -> Female | R10: =_xlfn.XLOOKUP(Sales_fact[[#This Row],[Product_ID]],Product_Dim!A:A,Product_Dim!C:C,"OTHERS") -> Home | T10: Kurtosis | U10: 0.059022757
A11: SALE9 | B11: 45869 | C11: CUST1464 | D11: PROD33 | E11: =TRIM(Sales_fact[[#This Row],[Store_ID]]) -> STORE0 | F11: 2 | G11: =IF(ISBLANK(F11),MODE($F$2:$F$2001),F11) -> 2 | H11: 873.17 | I11: =IF(ISBLANK(H11),AVERAGE($H$2:$H$2001),H11) -> 873.17 | J11: 0.23 | K11: =IF(ISBLANK(J11),MODE($J$2:$J$2001),J11) -> 0.23 | L11: PayPal | M11: 1344.6818 | N11: =G11*I11*(1-K11) -> 1344.6818 | O11: =_xlfn.XLOOKUP(Sales_fact[[#This Row],[Customer_ID]],'Customer_Dim'!A:A,'Customer_Dim'!K:K,"Not Found") -> Not Found | P11: =_xlfn.XLOOKUP(Sales_fact[[#This Row],[Customer_ID]],'Customer_Dim'!A:A, 'Customer_Dim'!E:E, "Not Found") -> Not Found | Q11: =VLOOKUP(Sales_fact[[#This Row],[Customer_ID]], 'Customer_Dim'!A:F, 6, ) -> #N/A | R11: =_xlfn.XLOOKUP(Sales_fact[[#This Row],[Product_ID]],Product_Dim!A:A,Product_Dim!C:C,"OTHERS") -> Home | T11: Skewness | U11: 0.8819083
A12: SALE10 | B12: 45335 | C12: CUST1065 | D12: PROD24 | E12: =TRIM(Sales_fact[[#This Row],[Store_ID]]) -> STORE14 | F12: 1 | G12: =IF(ISBLANK(F12),MODE($F$2:$F$2001),F12) -> 1 | H12: 278.63 | I12: =IF(ISBLANK(H12),AVERAGE($H$2:$H$2001),H12) -> 278.63 | J12: 0.07 | K12: =IF(ISBLANK(J12),MODE($J$2:$J$2001),J12) -> 0.07 | L12: Credit Card | M12: 259.1259 | N12: =G12*I12*(1-K12) -> 259.1259 | O12: =_xlfn.XLOOKUP(Sales_fact[[#This Row],[Customer_ID]],'Customer_Dim'!A:A,'Customer_Dim'!K:K,"Not Found") -> Silver | P12: =_xlfn.XLOOKUP(Sales_fact[[#This Row],[Customer_ID]],'Customer_Dim'!A:A, 'Customer_Dim'!E:E, "Not Found") -> 21 | Q12: =VLOOKUP(Sales_fact[[#This Row],[Customer_ID]], 'Customer_Dim'!A:F, 6, FALSE) -> Female | R12: =_xlfn.XLOOKUP(Sales_fact[[#This Row],[Product_ID]],Product_Dim!A:A,Product_Dim!C:C,"OTHERS") -> Sports | T12: Range | U12: 3889.7838
A13: SALE11 | B13: 45801 | C13: CUST1320 | D13: PROD39 | E13: =TRIM(Sales_fact[[#This Row],[Store_ID]]) -> STORE1 | F13: 4 | G13: =IF(ISBLANK(F13),MODE($F$2:$F$2001),F13) -> 4 | H13: 286.92 | I13: =IF(ISBLANK(H13),AVERAGE($H$2:$H$2001),H13) -> 286.92 | J13: 0.17 | K13: =IF(ISBLANK(J13),MODE($J$2:$J$2001),J13) -> 0.17 | L13: Credit Card | M13: 952.5744 | N13: =G13*I13*(1-K13) -> 952.5744 | O13: =_xlfn.XLOOKUP(Sales_fact[[#This Row],[Customer_ID]],'Customer_Dim'!A:A,'Customer_Dim'!K:K,"Not Found") -> Bronze | P13: =_xlfn.XLOOKUP(Sales_fact[[#This Row],[Customer_ID]],'Customer_Dim'!A:A, 'Customer_Dim'!E:E, "Not Found") -> 34 | Q13: =VLOOKUP(Sales_fact[[#This Row],[Customer_ID]], 'Customer_Dim'!A:F, 6, FALSE) -> Female | R13: =_xlfn.XLOOKUP(Sales_fact[[#This Row],[Product_ID]],Product_Dim!A:A,Product_Dim!C:C,"OTHERS") -> Electronics | T13: Minimum | U13: 18.459
A14: SALE12 | B14: 45528 | C14: CUST1237 | D14: PROD88 | E14: =TRIM(Sales_fact[[#This Row],[Store_ID]]) -> STORE4 | F14: 4 | G14: =IF(ISBLANK(F14),MODE($F$2:$F$2001),F14) -> 4 | H14: 644.58 | I14: =IF(ISBLANK(H14),AVERAGE($H$2:$H$2001),H14) -> 644.58 | J14: 0.01 | K14: =IF(ISBLANK(J14),MODE($J$2:$J$2001),J14) -> 0.01 | L14: Credit Card | M14: 2552.5368 | N14: =G14*I14*(1-K14) -> 2552.5368 | O14: =_xlfn.XLOOKUP(Sales_fact[[#This Row],[Customer_ID]],'Customer_Dim'!A:A,'Customer_Dim'!K:K,"Not Found") -> Gold | P14: =_xlfn.XLOOKUP(Sales_fact[[#This Row],[Customer_ID]],'Customer_Dim'!A:A, 'Customer_Dim'!E:E, "Not Found") -> 41 | Q14: =VLOOKUP(Sales_fact[[#This Row],[Customer_ID]], 'Customer_Dim'!A:F, 6, FALSE) -> Female | R14: =_xlfn.XLOOKUP(Sales_fact[[#This Row],[Product_ID]],Product_Dim!A:A,Product_Dim!C:C,"OTHERS") -> Sports | T14: Maximum | U14: 3908.2428
A15: SALE13 | B15: 45875 | C15: CUST1443 | D15: PROD34 | E15: =TRIM(Sales_fact[[#This Row],[Store_ID]]) -> STORE16 | F15: 2 | G15: =IF(ISBLANK(F15),MODE($F$2:$F$2001),F15) -> 2 | H15: 316.9 | I15: =IF(ISBLANK(H15),AVERAGE($H$2:$H$2001),H15) -> 316.9 | J15: 0.3 | K15: =IF(ISBLANK(J15),MODE($J$2:$J$2001),J15) -> 0.3 | L15: PayPal | M15: 443.66 | N15: =G15*I15*(1-K15) -> 443.66 | O15: =_xlfn.XLOOKUP(Sales_fact[[#This Row],[Customer_ID]],'Customer_Dim'!A:A,'Customer_Dim'!K:K,"Not Found") -> Silver | P15: =_xlfn.XLOOKUP(Sales_fact[[#This Row],[Customer_ID]],'Customer_Dim'!A:A, 'Customer_Dim'!E:E, "Not Found") -> 51 | Q15: =VLOOKUP(Sales_fact[[#This Row],[Customer_ID]], 'Customer_Dim'!A:F, 6, FALSE) -> Male | R15: =_xlfn.XLOOKUP(Sales_fact[[#This Row],[Product_ID]],Product_Dim!A:A,Product_Dim!C:C,"OTHERS") -> Electronics | T15: Sum | U15: 2173363.4
A16: SALE14 | B16: 45829 | C16: CUST1348 | D16: PROD24 | E16: =TRIM(Sales_fact[[#This Row],[Store_ID]]) -> STORE15 | F16: 4 | G16: =IF(ISBLANK(F16),MODE($F$2:$F$2001),F16) -> 4 | H16: 403.47 | I16: =IF(ISBLANK(H16),AVERAGE($H$2:$H$2001),H16) -> 403.47 | J16: 0.29 | K16: =IF(ISBLANK(J16),MODE($J$2:$J$2001),J16) -> 0.29 | L16: PayPal | M16: 1145.8548 | N16: =G16*I16*(1-K16) -> 1145.8548 | O16: =_xlfn.XLOOKUP(Sales_fact[[#This Row],[Customer_ID]],'Customer_Dim'!A:A,'Customer_Dim'!K:K,"Not Found") -> Silver | P16: =_xlfn.XLOOKUP(Sales_fact[[#This Row],[Customer_ID]],'Customer_Dim'!A:A, 'Customer_Dim'!E:E, "Not Found") -> 55 | Q16: =VLOOKUP(Sales_fact[[#This Row],[Customer_ID]], 'Customer_Dim'!A:F, 6, FALSE) -> Male | R16: =_xlfn.XLOOKUP(Sales_fact[[#This Row],[Product_ID]],Product_Dim!A:A,Product_Dim!C:C,"OTHERS") -> Sports | T16: Count | U16: 2000
A17: SALE15 | B17: 45636 | C17: CUST1435 | D17: PROD36 | E17: =TRIM(Sales_fact[[#This Row],[Store_ID]]) -> STORE9 | G17: =IF(ISBLANK(F17),MODE($F$2:$F$2001),F17) -> 2 | H17: 871.34 | I17: =IF(ISBLANK(H17),AVERAGE($H$2:$H$2001),H17) -> 871.34 | J17: 0.04 | K17: =IF(ISBLANK(J17),MODE($J$2:$J$2001),J17) -> 0.04 | L17: COD | M17: 2509.4592 | N17: =G17*I17*(1-K17) -> 1672.9728 | O17: =_xlfn.XLOOKUP(Sales_fact[[#This Row],[Customer_ID]],'Customer_Dim'!A:A,'Customer_Dim'!K:K,"Not Found") -> Silver | P17: =_xlfn.XLOOKUP(Sales_fact[[#This Row],[Customer_ID]],'Customer_Dim'!A:A, 'Customer_Dim'!E:E, "Not Found") -> 37 | Q17: =VLOOKUP(Sales_fact[[#This Row],[Customer_ID]], 'Customer_Dim'!A:F, 6, FALSE) -> Female | R17: =_xlfn.XLOOKUP(Sales_fact[[#This Row],[Product_ID]],Product_Dim!A:A,Product_Dim!C:C,"OTHERS") -> Clothing
A18: SALE16 | B18: 45913 | C18: CUST1276 | D18: PROD65 | E18: =TRIM(Sales_fact[[#This Row],[Store_ID]]) -> STORE19 | F18: 2 | G18: =IF(ISBLANK(F18),MODE($F$2:$F$2001),F18) -> 2 | H18: 451.98 | I18: =IF(ISBLANK(H18),AVERAGE($H$2:$H$2001),H18) -> 451.98 | J18: 0.25 | K18: =IF(ISBLANK(J18),MODE($J$2:$J$2001),J18) -> 0.25 | L18: Credit Card | M18: 677.97 | N18: =G18*I18*(1-K18) -> 677.97 | O18: =_xlfn.XLOOKUP(Sales_fact[[#This Row],[Customer_ID]],'Customer_Dim'!A:A,'Customer_Dim'!K:K,"Not Found") -> Gold | P18: =_xlfn.XLOOKUP(Sales_fact[[#This Row],[Customer_ID]],'Customer_Dim'!A:A, 'Customer_Dim'!E:E, "Not Found") -> 38 | Q18: =VLOOKUP(Sales_fact[[#This Row],[Customer_ID]], 'Customer_Dim'!A:F, 6, FALSE) -> Male | R18: =_xlfn.XLOOKUP(Sales_fact[[#This Row],[Product_ID]],Product_Dim!A:A,Product_Dim!C:C,"OTHERS") -> Sports
A19: SALE17 | B19: 45637 | C19: CUST1079 | D19: PROD27 | E19: =TRIM(Sales_fact[[#This Row],[Store_ID]]) -> STORE4 | F19: 2 | G19: =IF(ISBLANK(F19),MODE($F$2:$F$2001),F19) -> 2 | H19: 502.69 | I19: =IF(ISBLANK(H19),AVERAGE($H$2:$H$2001),H19) -> 502.69 | J19: 0.23 | K19: =IF(ISBLANK(J19),MODE($J$2:$J$2001),J19) -> 0.23 | L19: Credit Card | M19: 774.1426 | N19: =G19*I19*(1-K19) -> 774.1426 | O19: =_xlfn.XLOOKUP(Sales_fact[[#This Row],[Customer_ID]],'Customer_Dim'!A:A,'Customer_Dim'!K:K,"Not Found") -> Platinum | P19: =_xlfn.XLOOKUP(Sales_fact[[#This Row],[Customer_ID]],'Customer_Dim'!A:A, 'Customer_Dim'!E:E, "Not Found") -> 22 | Q19: =VLOOKUP(Sales_fact[[#This Row],[Customer_ID]], 'Customer_Dim'!A:F, 6, FALSE) -> Female | R19: =_xlfn.XLOOKUP(Sales_fact[[#This Row],[Product_ID]],Product_Dim!A:A,Product_Dim!C:C,"OTHERS") -> Home
A20: SALE18 | B20: 45517 | C20: CUST1094 | D20: PROD39 | E20: =TRIM(Sales_fact[[#This Row],[Store_ID]]) -> STORE4 | F20: 2 | G20: =IF(ISBLANK(F20),MODE($F$2:$F$2001),F20) -> 2 | H20: 559.23 | I20: =IF(ISBLANK(H20),AVERAGE($H$2:$H$2001),H20) -> 559.23 | J20: 0.25 | K20: =IF(ISBLANK(J20),MODE($J$2:$J$2001),J20) -> 0.25 | L20: COD | M20: 838.845 | N20: =G20*I20*(1-K20) -> 838.845 | O20: =_xlfn.XLOOKUP(Sales_fact[[#This Row],[Customer_ID]],'Customer_Dim'!A:A,'Customer_Dim'!K:K,"Not Found") -> Gold | P20: =_xlfn.XLOOKUP(Sales_fact[[#This Row],[Customer_ID]],'Customer_Dim'!A:A, 'Customer_Dim'!E:E, "Not Found") -> 43 | Q20: =VLOOKUP(Sales_fact[[#This Row],[Customer_ID]], 'Customer_Dim'!A:F, 6, FALSE) -> Female | R20: =_xlfn.XLOOKUP(Sales_fact[[#This Row],[Product_ID]],Product_Dim!A:A,Product_Dim!C:C,"OTHERS") -> Electronics
A21: SALE19 | B21: 45369 | C21: CUST1239 | D21: PROD60 | E21: =TRIM(Sales_fact[[#This Row],[Store_ID]]) -> STORE13 | F21: 4 | G21: =IF(ISBLANK(F21),MODE($F$2:$F$2001),F21) -> 4 | I21: =IF(ISBLANK(H21),AVERAGE($H$2:$H$2001),H21) -> 513.98477 | J21: 0.04 | K21: =IF(ISBLANK(J21),MODE($J$2:$J$2001),J21) -> 0.04 | L21: COD | M21: 1782.4512 | N21: =G21*I21*(1-K21) -> 1973.7015 | O21: =_xlfn.XLOOKUP(Sales_fact[[#This Row],[Customer_ID]],'Customer_Dim'!A:A,'Customer_Dim'!K:K,"Not Found") -> Platinum | P21: =_xlfn.XLOOKUP(Sales_fact[[#This Row],[Customer_ID]],'Customer_Dim'!A:A, 'Customer_Dim'!E:E, "Not Found") -> 58 | Q21: =VLOOKUP(Sales_fact[[#This Row],[Customer_ID]], 'Customer_Dim'!A:F, 6, FALSE) -> Female | R21: =_xlfn.XLOOKUP(Sales_fact[[#This Row],[Product_ID]],Product_Dim!A:A,Product_Dim!C:C,"OTHERS") -> Beauty
A22: SALE20 | B22: 45843 | C22: CUST1144 | D22: PROD72 | E22: =TRIM(Sales_fact[[#This Row],[Store_ID]]) -> STORE17 | F22: 3 | G22: =IF(ISBLANK(F22),MODE($F$2:$F$2001),F22) -> 3 | H22: 986.04 | I22: =IF(ISBLANK(H22),AVERAGE($H$2:$H$2001),H22) -> 986.04 | J22: 0.27 | K22: =IF(ISBLANK(J22),MODE($J$2:$J$2001),J22) -> 0.27 | L22: COD | M22: 2159.4276 | N22: =G22*I22*(1-K22) -> 2159.4276 | O22: =_xlfn.XLOOKUP(Sales_fact[[#This Row],[Customer_ID]],'Customer_Dim'!A:A,'Customer_Dim'!K:K,"Not Found") -> Bronze | P22: =_xlfn.XLOOKUP(Sales_fact[[#This Row],[Customer_ID]],'Customer_Dim'!A:A, 'Customer_Dim'!E:E, "Not Found") -> 62 | Q22: =VLOOKUP(Sales_fact[[#This Row],[Customer_ID]], 'Customer_Dim'!A:F, 6, FALSE) -> Female | R22: =_xlfn.XLOOKUP(Sales_fact[[#This Row],[Product_ID]],Product_Dim!A:A,Product_Dim!C:C,"OTHERS") -> Sports
A23: SALE21 | B23: 45447 | C23: CUST1396 | D23: PROD43 | E23: =TRIM(Sales_fact[[#This Row],[Store_ID]]) -> STORE18 | F23: 1 | G23: =IF(ISBLANK(F23),MODE($F$2:$F$2001),F23) -> 1 | H23: 589.56 | I23: =IF(ISBLANK(H23),AVERAGE($H$2:$H$2001),H23) -> 589.56 | J23: 0.22 | K23: =IF(ISBLANK(J23),MODE($J$2:$J$2001),J23) -> 0.22 | L23: Credit Card | M23: 459.8568 | N23: =G23*I23*(1-K23) -> 459.8568 | O23: =_xlfn.XLOOKUP(Sales_fact[[#This Row],[Customer_ID]],'Customer_Dim'!A:A,'Customer_Dim'!K:K,"Not Found") -> Silver | P23: =_xlfn.XLOOKUP(Sales_fact[[#This Row],[Customer_ID]],'Customer_Dim'!A:A, 'Customer_Dim'!E:E, "Not Found") -> 25 | Q23: =VLOOKUP(Sales_fact[[#This Row],[Customer_ID]], 'Customer_Dim'!A:F, 6, FALSE) -> Female | R23: =_xlfn.XLOOKUP(Sales_fact[[#This Row],[Product_ID]],Product_Dim!A:A,Product_Dim!C:C,"OTHERS") -> Electronics
A24: SALE22 | B24: 45394 | C24: CUST1476 | D24: PROD69 | E24: =TRIM(Sales_fact[[#This Row],[Store_ID]]) -> STORE10 | F24: 3 | G24: =IF(ISBLANK(F24),MODE($F$2:$F$2001),F24) -> 3 | H24: 979.42 | I24: =IF(ISBLANK(H24),AVERAGE($H$2:$H$2001),H24) -> 979.42 | J24: 0.03 | K24: =IF(ISBLANK(J24),MODE($J$2:$J$2001),J24) -> 0.03 | L24: PayPal | M24: 2850.1122 | N24: =G24*I24*(1-K24) -> 2850.1122 | O24: =_xlfn.XLOOKUP(Sales_fact[[#This Row],[Customer_ID]],'Customer_Dim'!A:A,'Customer_Dim'!K:K,"Not Found") -> Gold | P24: =_xlfn.XLOOKUP(Sales_fact[[#This Row],[Customer_ID]],'Customer_Dim'!A:A, 'Customer_Dim'!E:E, "Not Found") -> 33 | Q24: =VLOOKUP(Sales_fact[[#This Row],[Customer_ID]], 'Customer_Dim'!A:F, 6, FALSE) -> Female | R24: =_xlfn.XLOOKUP(Sales_fact[[#This Row],[Product_ID]],Product_Dim!A:A,Product_Dim!C:C,"OTHERS") -> Clothing
A25: SALE23 | B25: 45466 | C25: CUST1368 | D25: PROD12 | E25: =TRIM(Sales_fact[[#This Row],[Store_ID]]) -> STORE8 | F25: 1 | G25: =IF(ISBLANK(F25),MODE($F$2:$F$2001),F25) -> 1 | H25: 719.28 | I25: =IF(ISBLANK(H25),AVERAGE($H$2:$H$2001),H25) -> 719.28 | J25: 0.08 | K25: =IF(ISBLANK(J25),MODE($J$2:$J$2001),J25) -> 0.08 | L25: Credit Card | M25: 661.7376 | N25: =G25*I25*(1-K25) -> 661.7376 | O25: =_xlfn.XLOOKUP(Sales_fact[[#This Row],[Customer_ID]],'Customer_Dim'!A:A,'Customer_Dim'!K:K,"Not Found") -> Platinum | P25: =_xlfn.XLOOKUP(Sales_fact[[#This Row],[Customer_ID]],'Customer_Dim'!A:A, 'Customer_Dim'!E:E, "Not Found") -> 34 | Q25: =VLOOKUP(Sales_fact[[#This Row],[Customer_ID]], 'Customer_Dim'!A:F, 6, FALSE) -> Female | R25: =_xlfn.XLOOKUP(Sales_fact[[#This Row],[Product_ID]],Product_Dim!A:A,Product_Dim!C:C,"OTHERS") -> Beauty
A26: SALE24 | B26: 45908 | C26: CUST1186 | D26: PROD67 | E26: =TRIM(Sales_fact[[#This Row],[Store_ID]]) -> STORE6 | F26: 3 | G26: =IF(ISBLANK(F26),MODE($F$2:$F$2001),F26) -> 3 | H26: 77.6 | I26: =IF(ISBLANK(H26),AVERAGE($H$2:$H$2001),H26) -> 77.6 | J26: 0.07 | K26: =IF(ISBLANK(J26),MODE($J$2:$J$2001),J26) -> 0.07 | L26: Credit Card | M26: 216.504 | N26: =G26*I26*(1-K26) -> 216.504 | O26: =_xlfn.XLOOKUP(Sales_fact[[#This Row],[Customer_ID]],'Customer_Dim'!A:A,'Customer_Dim'!K:K,"Not Found") -> Silver | P26: =_xlfn.XLOOKUP(Sales_fact[[#This Row],[Customer_ID]],'Customer_Dim'!A:A, 'Customer_Dim'!E:E, "Not Found") -> 53 | Q26: =VLOOKUP(Sales_fact[[#This Row],[Customer_ID]], 'Customer_Dim'!A:F, 6, FALSE) -> Male | R26: =_xlfn.XLOOKUP(Sales_fact[[#This Row],[Product_ID]],Product_Dim!A:A,Product_Dim!C:C,"OTHERS") -> Electronics
A27: SALE25 | B27: 45552 | C27: CUST1381 | D27: PROD5 | E27: =TRIM(Sales_fact[[#This Row],[Store_ID]]) -> STORE3 | F27: 4 | G27: =IF(ISBLANK(F27),MODE($F$2:$F$2001),F27) -> 4 | H27: 852.71 | I27: =IF(ISBLANK(H27),AVERAGE($H$2:$H$2001),H27) -> 852.71 | J27: 0.14 | K27: =IF(ISBLANK(J27),MODE($J$2:$J$2001),J27) -> 0.14 | L27: PayPal | M27: 2933.3224 | N27: =G27*I27*(1-K27) -> 2933.3224 | O27: =_xlfn.XLOOKUP(Sales_fact[[#This Row],[Customer_ID]],'Customer_Dim'!A:A,'Customer_Dim'!K:K,"Not Found") -> Silver | P27: =_xlfn.XLOOKUP(Sales_fact[[#This Row],[Customer_ID]],'Customer_Dim'!A:A, 'Customer_Dim'!E:E, "Not Found") -> 50 | Q27: =VLOOKUP(Sales_fact[[#This Row],[Customer_ID]], 'Customer_Dim'!A:F, 6, FALSE) -> Male | R27: =_xlfn.XLOOKUP(Sales_fact[[#This Row],[Product_ID]],Product_Dim!A:A,Product_Dim!C:C,"OTHERS") -> Clothing
A28: SALE26 | B28: 45294 | C28: CUST1213 | D28: PROD98 | E28: =TRIM(Sales_fact[[#This Row],[Store_ID]]) -> STORE8 | F28: 4 | G28: =IF(ISBLANK(F28),MODE($F$2:$F$2001),F28) -> 4 | H28: 156.16 | I28: =IF(ISBLANK(H28),AVERAGE($H$2:$H$2001),H28) -> 156.16 | K28: =IF(ISBLANK(J28),MODE($J$2:$J$2001),J28) -> 0.1 | L28: Credit Card | M28: 599.6544 | N28: =G28*I28*(1-K28) -> 562.176 | O28: =_xlfn.XLOOKUP(Sales_fact[[#This Row],[Customer_ID]],'Customer_Dim'!A:A,'Customer_Dim'!K:K,"Not Found") -> Platinum | P28: =_xlfn.XLOOKUP(Sales_fact[[#This Row],[Customer_ID]],'Customer_Dim'!A:A, 'Customer_Dim'!E:E, "Not Found") -> 42 | Q28: =VLOOKUP(Sales_fact[[#This Row],[Customer_ID]], 'Customer_Dim'!A:F, 6, FALSE) -> Female | R28: =_xlfn.XLOOKUP(Sales_fact[[#This Row],[Product_ID]],Product_Dim!A:A,Product_Dim!C:C,"OTHERS") -> Electronics
A29: SALE27 | B29: 45710 | C29: CUST1200 | D29: PROD77 | E29: =TRIM(Sales_fact[[#This Row],[Store_ID]]) -> STORE8 | F29: 3 | G29: =IF(ISBLANK(F29),MODE($F$2:$F$2001),F29) -> 3 | H29: 815.49 | I29: =IF(ISBLANK(H29),AVERAGE($H$2:$H$2001),H29) -> 815.49 | J29: 0.17 | K29: =IF(ISBLANK(J29),MODE($J$2:$J$2001),J29) -> 0.17 | L29: Credit Card | M29: 2030.5701 | N29: =G29*I29*(1-K29) -> 2030.5701 | O29: =_xlfn.XLOOKUP(Sales_fact[[#This Row],[Customer_ID]],'Customer_Dim'!A:A,'Customer_Dim'!K:K,"Not Found") -> Platinum | P29: =_xlfn.XLOOKUP(Sales_fact[[#This Row],[Customer_ID]],'Customer_Dim'!A:A, 'Customer_Dim'!E:E, "Not Found") -> 30 | Q29: =VLOOKUP(Sales_fact[[#This Row],[Customer_ID]], 'Customer_Dim'!A:F, 6, FALSE) -> Male | R29: =_xlfn.XLOOKUP(Sales_fact[[#This Row],[Product_ID]],Product_Dim!A:A,Product_Dim!C:C,"OTHERS") -> Electronics
A30: SALE28 | B30: 45923 | C30: CUST1148 | D30: PROD13 | E30: =TRIM(Sales_fact[[#This Row],[Store_ID]]) -> STORE2 | F30: 2 | G30: =IF(ISBLANK(F30),MODE($F$2:$F$2001),F30) -> 2 | H30: 74.21 | I30: =IF(ISBLANK(H30),AVERAGE($H$2:$H$2001),H30) -> 74.21 | J30: 0.11 | K30: =IF(ISBLANK(J30),MODE($J$2:$J$2001),J30) -> 0.11 | L30: PayPal | M30: 132.0938 | N30: =G30*I30*(1-K30) -> 132.0938 | O30: =_xlfn.XLOOKUP(Sales_fact[[#This Row],[Customer_ID]],'Customer_Dim'!A:A,'Customer_Dim'!K:K,"Not Found") -> Bronze | P30: =_xlfn.XLOOKUP(Sales_fact[[#This Row],[Customer_ID]],'Customer_Dim'!A:A, 'Customer_Dim'!E:E, "Not Found") -> 42 | Q30: =VLOOKUP(Sales_fact[[#This Row],[Customer_ID]], 'Customer_Dim'!A:F, 6, FALSE) -> Female | R30: =_xlfn.XLOOKUP(Sales_fact[[#This Row],[Product_ID]],Product_Dim!A:A,Product_Dim!C:C,"OTHERS") -> Electronics
A31: SALE29 | B31: 45302 | C31: CUST1348 | D31: PROD99 | E31: =TRIM(Sales_fact[[#This Row],[Store_ID]]) -> STORE3 | G31: =IF(ISBLANK(F31),MODE($F$2:$F$2001),F31) -> 2 | H31: 451.67 | I31: =IF(ISBLANK(H31),AVERAGE($H$2:$H$2001),H31) -> 451.67 | J31: 0.15 | K31: =IF(ISBLANK(J31),MODE($J$2:$J$2001),J31) -> 0.15 | L31: Credit Card | M31: 1535.678 | N31: =G31*I31*(1-K31) -> 767.839 | O31: =_xlfn.XLOOKUP(Sales_fact[[#This Row],[Customer_ID]],'Customer_Dim'!A:A,'Customer_Dim'!K:K,"Not Found") -> Silver | P31: =_xlfn.XLOOKUP(Sales_fact[[#This Row],[Customer_ID]],'Customer_Dim'!A:A, 'Customer_Dim'!E:E, "Not Found") -> 55 | Q31: =VLOOKUP(Sales_fact[[#This Row],[Customer_ID]], 'Customer_Dim'!A:F, 6, FALSE) -> Male | R31: =_xlfn.XLOOKUP(Sales_fact[[#This Row],[Product_ID]],Product_Dim!A:A,Product_Dim!C:C,"OTHERS") -> Home
A32: SALE30 | B32: 45217 | C32: CUST1028 | D32: PROD5 | E32: =TRIM(Sales_fact[[#This Row],[Store_ID]]) -> STORE19 | F32: 1 | G32: =IF(ISBLANK(F32),MODE($F$2:$F$2001),F32) -> 1 | H32: 429.38 | I32: =IF(ISBLANK(H32),AVERAGE($H$2:$H$2001),H32) -> 429.38 | J32: 0.13 | K32: =IF(ISBLANK(J32),MODE($J$2:$J$2001),J32) -> 0.13 | L32: PayPal | M32: 373.5606 | N32: =G32*I32*(1-K32) -> 373.5606 | O32: =_xlfn.XLOOKUP(Sales_fact[[#This Row],[Customer_ID]],'Customer_Dim'!A:A,'Customer_Dim'!K:K,"Not Found") -> Platinum | P32: =_xlfn.XLOOKUP(Sales_fact[[#This Row],[Customer_ID]],'Customer_Dim'!A:A, 'Customer_Dim'!E:E, "Not Found") -> 27 | Q32: =VLOOKUP(Sales_fact[[#This Row],[Customer_ID]], 'Customer_Dim'!A:F, 6, FALSE) -> Female | R32: =_xlfn.XLOOKUP(Sales_fact[[#This Row],[Product_ID]],Product_Dim!A:A,Product_Dim!C:C,"OTHERS") -> Clothing
A33: SALE31 | B33: 45593 | C33: CUST1412 | D33: PROD53 | E33: =TRIM(Sales_fact[[#This Row],[Store_ID]]) -> STORE12 | F33: 2 | G33: =IF(ISBLANK(F33),MODE($F$2:$F$2001),F33) -> 2 | H33: 148.96 | I33: =IF(ISBLANK(H33),AVERAGE($H$2:$H$2001),H33) -> 148.96 | J33: 0.03 | K33: =IF(ISBLANK(J33),MODE($J$2:$J$2001),J33) -> 0.03 | L33: COD | M33: 288.9824 | N33: =G33*I33*(1-K33) -> 288.9824 | O33: =_xlfn.XLOOKUP(Sales_fact[[#This Row],[Customer_ID]],'Customer_Dim'!A:A,'Customer_Dim'!K:K,"Not Found") -> Gold | P33: =_xlfn.XLOOKUP(Sales_fact[[#This Row],[Customer_ID]],'Customer_Dim'!A:A, 'Customer_Dim'!E:E, "Not Found") -> 23 | Q33: =VLOOKUP(Sales_fact[[#This Row],[Customer_ID]], 'Customer_Dim'!A:F, 6, FALSE) -> Female | R33: =_xlfn.XLOOKUP(Sales_fact[[#This Row],[Product_ID]],Product_Dim!A:A,Product_Dim!C:C,"OTHERS") -> Clothing
A34: SALE32 | B34: 45597 | C34: CUST1398 | D34: PROD75 | E34: =TRIM(Sales_fact[[#This Row],[Store_ID]]) -> STORE8 | F34: 4 | G34: =IF(ISBLANK(F34),MODE($F$2:$F$2001),F34) -> 4 | H34: 313.83 | I34: =IF(ISBLANK(H34),AVERAGE($H$2:$H$2001),H34) -> 313.83 | J34: 0.08 | K34: =IF(ISBLANK(J34),MODE($J$2:$J$2001),J34) -> 0.08 | L34: Credit Card | M34: 1154.8944 | N34: =G34*I34*(1-K34) -> 1154.8944 | O34: =_xlfn.XLOOKUP(Sales_fact[[#This Row],[Customer_ID]],'Customer_Dim'!A:A,'Customer_Dim'!K:K,"Not Found") -> Bronze | P34: =_xlfn.XLOOKUP(Sales_fact[[#This Row],[Customer_ID]],'Customer_Dim'!A:A, 'Customer_Dim'!E:E, "Not Found") -> 54 | Q34: =VLOOKUP(Sales_fact[[#This Row],[Customer_ID]], 'Customer_Dim'!A:F, 6, FALSE) -> Male | R34: =_xlfn.XLOOKUP(Sales_fact[[#This Row],[Product_ID]],Product_Dim!A:A,Product_Dim!C:C,"OTHERS") -> Clothing
A35: SALE33 | B35: 45620 | C35: CUST1453 | D35: PROD12 | E35: =TRIM(Sales_fact[[#This Row],[Store_ID]]) -> STORE6 | F35: 2 | G35: =IF(ISBLANK(F35),MODE($F$2:$F$2001),F35) -> 2 | H35: 717.31 | I35: =IF(ISBLANK(H35),AVERAGE($H$2:$H$2001),H35) -> 717.31 | J35: 0.15 | K35: =IF(ISBLANK(J35),MODE($J$2:$J$2001),J35) -> 0.15 | L35: Credit Card | M35: 1219.427 | N35: =G35*I35*(1-K35) -> 1219.427 | O35: =_xlfn.XLOOKUP(Sales_fact[[#This Row],[Customer_ID]],'Customer_Dim'!A:A,'Customer_Dim'!K:K,"Not Found") -> Platinum | P35: =_xlfn.XLOOKUP(Sales_fact[[#This Row],[Customer_ID]],'Customer_Dim'!A:A, 'Customer_Dim'!E:E, "Not Found") -> 62 | Q35: =VLOOKUP(Sales_fact[[#This Row],[Customer_ID]], 'Customer_Dim'!A:F, 6, FALSE) -> Female | R35: =_xlfn.XLOOKUP(Sales_fact[[#This Row],[Product_ID]],Product_Dim!A:A,Product_Dim!C:C,"OTHERS") -> Beauty
A36: SALE34 | B36: 45215 | C36: CUST1344 | D36: PROD79 | E36: =TRIM(Sales_fact[[#This Row],[Store_ID]]) -> STORE1 | G36: =IF(ISBLANK(F36),MODE($F$2:$F$2001),F36) -> 2 | H36: 873.22 | I36: =IF(ISBLANK(H36),AVERAGE($H$2:$H$2001),H36) -> 873.22 | J36: 0.18 | K36: =IF(ISBLANK(J36),MODE($J$2:$J$2001),J36) -> 0.18 | L36: Credit Card | M36: 2148.1212 | N36: =G36*I36*(1-K36) -> 1432.0808 | O36: =_xlfn.XLOOKUP(Sales_fact[[#This Row],[Customer_ID]],'Customer_Dim'!A:A,'Customer_Dim'!K:K,"Not Found") -> Gold | P36: =_xlfn.XLOOKUP(Sales_fact[[#This Row],[Customer_ID]],'Customer_Dim'!A:A, 'Customer_Dim'!E:E, "Not Found") -> 39 | Q36: =VLOOKUP(Sales_fact[[#This Row],[Customer_ID]], 'Customer_Dim'!A:F, 6, FALSE) -> Male | R36: =_xlfn.XLOOKUP(Sales_fact[[#This Row],[Product_ID]],Product_Dim!A:A,Product_Dim!C:C,"OTHERS") -> Home
A37: SALE35 | B37: 45878 | C37: CUST1218 | D37: PROD16 | E37: =TRIM(Sales_fact[[#This Row],[Store_ID]]) -> STORE3 | F37: 4 | G37: =IF(ISBLANK(F37),MODE($F$2:$F$2001),F37) -> 4 | H37: 109.36 | I37: =IF(ISBLANK(H37),AVERAGE($H$2:$H$2001),H37) -> 109.36 | J37: 0.19 | K37: =IF(ISBLANK(J37),MODE($J$2:$J$2001),J37) -> 0.19 | L37: COD | M37: 354.3264 | N37: =G37*I37*(1-K37) -> 354.3264 | O37: =_xlfn.XLOOKUP(Sales_fact[[#This Row],[Customer_ID]],'Customer_Dim'!A:A,'Customer_Dim'!K:K,"Not Found") -> Platinum | P37: =_xlfn.XLOOKUP(Sales_fact[[#This Row],[Customer_ID]],'Customer_Dim'!A:A, 'Customer_Dim'!E:E, "Not Found") -> 46 | Q37: =VLOOKUP(Sales_fact[[#This Row],[Customer_ID]], 'Customer_Dim'!A:F, 6, FALSE) -> Male | R37: =_xlfn.XLOOKUP(Sales_fact[[#This Row],[Product_ID]],Product_Dim!A:A,Product_Dim!C:C,"OTHERS") -> OTHERS
A38: SALE36 | B38: 45635 | C38: CUST1086 | D38: PROD5 | E38: =TRIM(Sales_fact[[#This Row],[Store_ID]]) -> STORE7 | F38: 3 | G38: =IF(ISBLANK(F38),MODE($F$2:$F$2001),F38) -> 3 | H38: 559.52 | I38: =IF(ISBLANK(H38),AVERAGE($H$2:$H$2001),H38) -> 559.52 | J38: 0.16 | K38: =IF(ISBLANK(J38),MODE($J$2:$J$2001),J38) -> 0.16 | L38: PayPal | M38: 1409.9904 | N38: =G38*I38*(1-K38) -> 1409.9904 | O38: =_xlfn.XLOOKUP(Sales_fact[[#This Row],[Customer_ID]],'Customer_Dim'!A:A,'Customer_Dim'!K:K,"Not Found") -> Gold | P38: =_xlfn.XLOOKUP(Sales_fact[[#This Row],[Customer_ID]],'Customer_Dim'!A:A, 'Customer_Dim'!E:E, "Not Found") -> 19 | Q38: =VLOOKUP(Sales_fact[[#This Row],[Customer_ID]], 'Customer_Dim'!A:F, 6, FALSE) -> Female | R38: =_xlfn.XLOOKUP(Sales_fact[[#This Row],[Product_ID]],Product_Dim!A:A,Product_Dim!C:C,"OTHERS") -> Clothing
A39: SALE37 | B39: 45329 | C39: CUST1492 | D39: PROD10 | E39: =TRIM(Sales_fact[[#This Row],[Store_ID]]) -> STORE17 | F39: 3 | G39: =IF(ISBLANK(F39),MODE($F$2:$F$2001),F39) -> 3 | H39: 121.76 | I39: =IF(ISBLANK(H39),AVERAGE($H$2:$H$2001),H39) -> 121.76 | J39: 0.27 | K39: =IF(ISBLANK(J39),MODE($J$2:$J$2001),J39) -> 0.27 | L39: PayPal | M39: 266.6544 | N39: =G39*I39*(1-K39) -> 266.6544 | O39: =_xlfn.XLOOKUP(Sales_fact[[#This Row],[Customer_ID]],'Customer_Dim'!A:A,'Customer_Dim'!K:K,"Not Found") -> Platinum | P39: =_xlfn.XLOOKUP(Sales_fact[[#This Row],[Customer_ID]],'Customer_Dim'!A:A, 'Customer_Dim'!E:E, "Not Found") -> 59 | Q39: =VLOOKUP(Sales_fact[[#This Row],[Customer_ID]], 'Customer_Dim'!A:F, 6, FALSE) -> Female | R39: =_xlfn.XLOOKUP(Sales_fact[[#This Row],[Product_ID]],Product_Dim!A:A,Product_Dim!C:C,"OTHERS") -> Home
